[32m2025-06-27 07:48:46 +0200[0m - dagster - [34mDEBUG[0m - __ASSET_JOB - e290689c-5125-48d5-8902-0cdb940a1cd9 - 38975 - LOGS_CAPTURED - Started capturing logs in process (pid: 38975).
[32m2025-06-27 07:48:46 +0200[0m - dagster - [34mDEBUG[0m - __ASSET_JOB - e290689c-5125-48d5-8902-0cdb940a1cd9 - 38975 - simulate_data - STEP_START - Started execution of step "simulate_data".
[32m2025-06-27 07:48:46 +0200[0m - dagster - [34mERROR[0m - [31m__ASSET_JOB - e290689c-5125-48d5-8902-0cdb940a1cd9 - 38975 - simulate_data - STEP_FAILURE - Execution of step "simulate_data" failed.

dagster._core.errors.DagsterExecutionStepExecutionError: Error occurred while executing op "simulate_data"::

NameError: name 'duckdb' is not defined

Stack Trace:
  File "/Library/Frameworks/Python.framework/Versions/3.11/lib/python3.11/site-packages/dagster/_core/execution/plan/utils.py", line 56, in op_execution_error_boundary
    yield
  File "/Library/Frameworks/Python.framework/Versions/3.11/lib/python3.11/site-packages/dagster/_utils/__init__.py", line 392, in iterate_with_context
    next_output = next(iterator)
                  ^^^^^^^^^^^^^^
  File "/Library/Frameworks/Python.framework/Versions/3.11/lib/python3.11/site-packages/dagster/_core/execution/plan/compute_generator.py", line 129, in _coerce_op_compute_fn_to_iterator
    result = invoke_compute_fn(
             ^^^^^^^^^^^^^^^^^^
  File "/Library/Frameworks/Python.framework/Versions/3.11/lib/python3.11/site-packages/dagster/_core/execution/plan/compute_generator.py", line 117, in invoke_compute_fn
    return fn(context, **args_to_pass) if context_arg_provided else fn(**args_to_pass)
           ^^^^^^^^^^^^^^^^^^^^^^^^^^^
  File "/Users/ekltn/Documents/skeleton-project/dagster/assets/demo_assets.py", line 39, in simulate_data
    with duckdb.get_connection() as conn:
         ^^^^^^
[0m
